{"uuid": "8df492b6-5cea-4cbd-898e-25eae34459db", "children": ["17e55e00-a552-451e-a56a-afab24bd0a97"], "befores": [{"name": "driver", "status": "broken", "statusDetails": {"message": "selenium.common.exceptions.SessionNotCreatedException: Message: session not created: probably user data directory is already in use, please specify a unique value for --user-data-dir argument, or don't use --user-data-dir\nStacktrace:\n#0 0x558277e69ffa <unknown>\n#1 0x558277928970 <unknown>\n#2 0x55827796242a <unknown>\n#3 0x55827795e18f <unknown>\n#4 0x5582779aebd9 <unknown>\n#5 0x5582779ae106 <unknown>\n#6 0x5582779a0063 <unknown>\n#7 0x55827796c328 <unknown>\n#8 0x55827796d491 <unknown>\n#9 0x558277e3142b <unknown>\n#10 0x558277e352ec <unknown>\n#11 0x558277e18a22 <unknown>\n#12 0x558277e35e64 <unknown>\n#13 0x558277dfcbef <unknown>\n#14 0x558277e58558 <unknown>\n#15 0x558277e58736 <unknown>\n#16 0x558277e68e76 <unknown>\n#17 0x7f7f1e0491f5 <unknown>\n\n", "trace": "  File \"/usr/local/lib/python3.9/site-packages/pluggy/_callers.py\", line 103, in _multicall\n    res = hook_impl.function(*args)\n  File \"/usr/local/lib/python3.9/site-packages/_pytest/fixtures.py\", line 1130, in pytest_fixture_setup\n    result = call_fixture_func(fixturefunc, request, kwargs)\n  File \"/usr/local/lib/python3.9/site-packages/_pytest/fixtures.py\", line 902, in call_fixture_func\n    fixture_result = next(generator)\n  File \"/app/tests/ui/ui_tests/conftest.py\", line 15, in driver\n    config_driver = webdriver.Chrome(service=service, options=options)\n  File \"/usr/local/lib/python3.9/site-packages/selenium/webdriver/chrome/webdriver.py\", line 49, in __init__\n    super().__init__(\n  File \"/usr/local/lib/python3.9/site-packages/selenium/webdriver/chromium/webdriver.py\", line 54, in __init__\n    super().__init__(\n  File \"/usr/local/lib/python3.9/site-packages/selenium/webdriver/remote/webdriver.py\", line 206, in __init__\n    self.start_session(capabilities)\n  File \"/usr/local/lib/python3.9/site-packages/selenium/webdriver/remote/webdriver.py\", line 291, in start_session\n    response = self.execute(Command.NEW_SESSION, caps)[\"value\"]\n  File \"/usr/local/lib/python3.9/site-packages/selenium/webdriver/remote/webdriver.py\", line 346, in execute\n    self.error_handler.check_response(response)\n  File \"/usr/local/lib/python3.9/site-packages/selenium/webdriver/remote/errorhandler.py\", line 245, in check_response\n    raise exception_class(message, screen, stacktrace)\n"}, "start": 1742639205264, "stop": 1742639206321}], "start": 1742639205264, "stop": 1742639206388}