{"uuid": "b0edd416-8c2c-44bd-acbc-1f2039cb7067", "children": ["270da970-d7e6-484e-a4af-b9ff52c04eb8"], "befores": [{"name": "driver", "status": "broken", "statusDetails": {"message": "selenium.common.exceptions.SessionNotCreatedException: Message: session not created: probably user data directory is already in use, please specify a unique value for --user-data-dir argument, or don't use --user-data-dir\nStacktrace:\n#0 0x5555b0f1affa <unknown>\n#1 0x5555b09d9970 <unknown>\n#2 0x5555b0a1342a <unknown>\n#3 0x5555b0a0f18f <unknown>\n#4 0x5555b0a5fbd9 <unknown>\n#5 0x5555b0a5f106 <unknown>\n#6 0x5555b0a51063 <unknown>\n#7 0x5555b0a1d328 <unknown>\n#8 0x5555b0a1e491 <unknown>\n#9 0x5555b0ee242b <unknown>\n#10 0x5555b0ee62ec <unknown>\n#11 0x5555b0ec9a22 <unknown>\n#12 0x5555b0ee6e64 <unknown>\n#13 0x5555b0eadbef <unknown>\n#14 0x5555b0f09558 <unknown>\n#15 0x5555b0f09736 <unknown>\n#16 0x5555b0f19e76 <unknown>\n#17 0x7f754e5e91f5 <unknown>\n\n", "trace": "  File \"/usr/local/lib/python3.9/site-packages/pluggy/_callers.py\", line 103, in _multicall\n    res = hook_impl.function(*args)\n  File \"/usr/local/lib/python3.9/site-packages/_pytest/fixtures.py\", line 1130, in pytest_fixture_setup\n    result = call_fixture_func(fixturefunc, request, kwargs)\n  File \"/usr/local/lib/python3.9/site-packages/_pytest/fixtures.py\", line 902, in call_fixture_func\n    fixture_result = next(generator)\n  File \"/app/tests/ui/ui_tests/conftest.py\", line 15, in driver\n    config_driver = webdriver.Chrome(service=service, options=options)\n  File \"/usr/local/lib/python3.9/site-packages/selenium/webdriver/chrome/webdriver.py\", line 49, in __init__\n    super().__init__(\n  File \"/usr/local/lib/python3.9/site-packages/selenium/webdriver/chromium/webdriver.py\", line 54, in __init__\n    super().__init__(\n  File \"/usr/local/lib/python3.9/site-packages/selenium/webdriver/remote/webdriver.py\", line 206, in __init__\n    self.start_session(capabilities)\n  File \"/usr/local/lib/python3.9/site-packages/selenium/webdriver/remote/webdriver.py\", line 291, in start_session\n    response = self.execute(Command.NEW_SESSION, caps)[\"value\"]\n  File \"/usr/local/lib/python3.9/site-packages/selenium/webdriver/remote/webdriver.py\", line 346, in execute\n    self.error_handler.check_response(response)\n  File \"/usr/local/lib/python3.9/site-packages/selenium/webdriver/remote/errorhandler.py\", line 245, in check_response\n    raise exception_class(message, screen, stacktrace)\n"}, "start": 1742639209619, "stop": 1742639210547}], "start": 1742639209619, "stop": 1742639210615}