{"name": "test_user_creates_task_duplicate", "status": "failed", "statusDetails": {"message": "AssertionError: Duplicate task found! Expected 1, but found 24\nassert 24 == 1", "trace": "driver = <selenium.webdriver.chrome.webdriver.WebDriver (session=\"01db62c4e125aef581da55fd5fc69d01\")>\n\n    @allure.feature(\"Operations with tasks\")\n    @allure.story(\"Check task duplicates\")\n    @allure.severity(allure.severity_level.NORMAL)\n    \n    def test_user_creates_task_duplicate(driver):\n        username = \"kate11\"\n        password = \"kate11\"\n        title = \"ola1\"\n        description = \"desc1\"\n    \n        with allure.step(\"Navigate to the login page and authenticate\"):\n            user_on_tasks = LoginPage(driver)\n            user_on_tasks.get_login_page()\n            user_on_tasks.authenticated_user(username, password)\n    \n        with allure.step(\"Verify successful login\"):\n            tasks = TasksPage(driver)\n            tasks.get_success_message()\n            assert \"Вы успешно вошли в систему\" in tasks.get_success_message(), \"User is not authorized\"\n    \n        with allure.step(\"Create a task with the same title and description\"):\n            tasks.click_new_task_btn()\n            assert \"create\" in driver.current_url, \"User is not on the new task creation page\"\n            tasks.enter_new_task_title(title)\n            tasks.enter_new_task_description(description)\n            tasks.submit_task()\n    \n            task_count = tasks.count_tasks_with_title_duplicate(title)\n>           assert task_count == 1, f\"Duplicate task found! Expected 1, but found {task_count}\"\nE           AssertionError: Duplicate task found! Expected 1, but found 24\nE           assert 24 == 1\n\ntests/ui/ui_tests/test_manage_tasks.py:72: AssertionError"}, "steps": [{"name": "Navigate to the login page and authenticate", "status": "passed", "start": 1742642098585, "stop": 1742642099044}, {"name": "Verify successful login", "status": "passed", "start": 1742642099044, "stop": 1742642099282}, {"name": "Create a task with the same title and description", "status": "failed", "statusDetails": {"message": "AssertionError: Duplicate task found! Expected 1, but found 24\nassert 24 == 1\n", "trace": "  File \"/app/tests/ui/ui_tests/test_manage_tasks.py\", line 72, in test_user_creates_task_duplicate\n    assert task_count == 1, f\"Duplicate task found! Expected 1, but found {task_count}\"\n"}, "start": 1742642099282, "stop": 1742642100451}], "start": 1742642098585, "stop": 1742642100457, "uuid": "5b8ea42d-0c4e-43f4-8510-ca99f7c3251c", "historyId": "b3e1cc818cbd971f22cfb32867aca882", "testCaseId": "b3e1cc818cbd971f22cfb32867aca882", "fullName": "tests.ui.ui_tests.test_manage_tasks#test_user_creates_task_duplicate", "labels": [{"name": "feature", "value": "Operations with tasks"}, {"name": "severity", "value": "normal"}, {"name": "story", "value": "Check task duplicates"}, {"name": "parentSuite", "value": "tests.ui.ui_tests"}, {"name": "suite", "value": "test_manage_tasks"}, {"name": "host", "value": "72ee90207c35"}, {"name": "thread", "value": "20-MainThread"}, {"name": "framework", "value": "pytest"}, {"name": "language", "value": "cpython3"}, {"name": "package", "value": "tests.ui.ui_tests.test_manage_tasks"}]}