{"uuid": "d57d8ae4-4757-474a-b6c8-a94c033bb063", "children": ["065a6d97-afa2-408a-b60b-94cadd163599"], "befores": [{"name": "driver", "status": "broken", "statusDetails": {"message": "selenium.common.exceptions.SessionNotCreatedException: Message: session not created: probably user data directory is already in use, please specify a unique value for --user-data-dir argument, or don't use --user-data-dir\nStacktrace:\n#0 0x5606d6ba9ffa <unknown>\n#1 0x5606d6668970 <unknown>\n#2 0x5606d66a242a <unknown>\n#3 0x5606d669e18f <unknown>\n#4 0x5606d66eebd9 <unknown>\n#5 0x5606d66ee106 <unknown>\n#6 0x5606d66e0063 <unknown>\n#7 0x5606d66ac328 <unknown>\n#8 0x5606d66ad491 <unknown>\n#9 0x5606d6b7142b <unknown>\n#10 0x5606d6b752ec <unknown>\n#11 0x5606d6b58a22 <unknown>\n#12 0x5606d6b75e64 <unknown>\n#13 0x5606d6b3cbef <unknown>\n#14 0x5606d6b98558 <unknown>\n#15 0x5606d6b98736 <unknown>\n#16 0x5606d6ba8e76 <unknown>\n#17 0x7f8d576eb1f5 <unknown>\n\n", "trace": "  File \"/usr/local/lib/python3.9/site-packages/pluggy/_callers.py\", line 103, in _multicall\n    res = hook_impl.function(*args)\n  File \"/usr/local/lib/python3.9/site-packages/_pytest/fixtures.py\", line 1130, in pytest_fixture_setup\n    result = call_fixture_func(fixturefunc, request, kwargs)\n  File \"/usr/local/lib/python3.9/site-packages/_pytest/fixtures.py\", line 902, in call_fixture_func\n    fixture_result = next(generator)\n  File \"/app/tests/ui/ui_tests/conftest.py\", line 15, in driver\n    config_driver = webdriver.Chrome(service=service, options=options)\n  File \"/usr/local/lib/python3.9/site-packages/selenium/webdriver/chrome/webdriver.py\", line 49, in __init__\n    super().__init__(\n  File \"/usr/local/lib/python3.9/site-packages/selenium/webdriver/chromium/webdriver.py\", line 54, in __init__\n    super().__init__(\n  File \"/usr/local/lib/python3.9/site-packages/selenium/webdriver/remote/webdriver.py\", line 206, in __init__\n    self.start_session(capabilities)\n  File \"/usr/local/lib/python3.9/site-packages/selenium/webdriver/remote/webdriver.py\", line 291, in start_session\n    response = self.execute(Command.NEW_SESSION, caps)[\"value\"]\n  File \"/usr/local/lib/python3.9/site-packages/selenium/webdriver/remote/webdriver.py\", line 346, in execute\n    self.error_handler.check_response(response)\n  File \"/usr/local/lib/python3.9/site-packages/selenium/webdriver/remote/errorhandler.py\", line 245, in check_response\n    raise exception_class(message, screen, stacktrace)\n"}, "start": 1742639206417, "stop": 1742639207522}], "start": 1742639206417, "stop": 1742639207564}