{"uuid": "e5b23bfe-af95-4f18-bbf0-e8cbf9558260", "children": ["3fb949e5-2824-4bce-a703-10ae9470b693"], "befores": [{"name": "driver", "status": "broken", "statusDetails": {"message": "selenium.common.exceptions.SessionNotCreatedException: Message: session not created: probably user data directory is already in use, please specify a unique value for --user-data-dir argument, or don't use --user-data-dir\nStacktrace:\n#0 0x56441d7ddffa <unknown>\n#1 0x56441d29c970 <unknown>\n#2 0x56441d2d642a <unknown>\n#3 0x56441d2d218f <unknown>\n#4 0x56441d322bd9 <unknown>\n#5 0x56441d322106 <unknown>\n#6 0x56441d314063 <unknown>\n#7 0x56441d2e0328 <unknown>\n#8 0x56441d2e1491 <unknown>\n#9 0x56441d7a542b <unknown>\n#10 0x56441d7a92ec <unknown>\n#11 0x56441d78ca22 <unknown>\n#12 0x56441d7a9e64 <unknown>\n#13 0x56441d770bef <unknown>\n#14 0x56441d7cc558 <unknown>\n#15 0x56441d7cc736 <unknown>\n#16 0x56441d7dce76 <unknown>\n#17 0x7efe113221f5 <unknown>\n\n", "trace": "  File \"/usr/local/lib/python3.9/site-packages/pluggy/_callers.py\", line 103, in _multicall\n    res = hook_impl.function(*args)\n  File \"/usr/local/lib/python3.9/site-packages/_pytest/fixtures.py\", line 1130, in pytest_fixture_setup\n    result = call_fixture_func(fixturefunc, request, kwargs)\n  File \"/usr/local/lib/python3.9/site-packages/_pytest/fixtures.py\", line 902, in call_fixture_func\n    fixture_result = next(generator)\n  File \"/app/tests/ui/ui_tests/conftest.py\", line 15, in driver\n    config_driver = webdriver.Chrome(service=service, options=options)\n  File \"/usr/local/lib/python3.9/site-packages/selenium/webdriver/chrome/webdriver.py\", line 49, in __init__\n    super().__init__(\n  File \"/usr/local/lib/python3.9/site-packages/selenium/webdriver/chromium/webdriver.py\", line 54, in __init__\n    super().__init__(\n  File \"/usr/local/lib/python3.9/site-packages/selenium/webdriver/remote/webdriver.py\", line 206, in __init__\n    self.start_session(capabilities)\n  File \"/usr/local/lib/python3.9/site-packages/selenium/webdriver/remote/webdriver.py\", line 291, in start_session\n    response = self.execute(Command.NEW_SESSION, caps)[\"value\"]\n  File \"/usr/local/lib/python3.9/site-packages/selenium/webdriver/remote/webdriver.py\", line 346, in execute\n    self.error_handler.check_response(response)\n  File \"/usr/local/lib/python3.9/site-packages/selenium/webdriver/remote/errorhandler.py\", line 245, in check_response\n    raise exception_class(message, screen, stacktrace)\n"}, "start": 1742639200814, "stop": 1742639201742}], "start": 1742639200814, "stop": 1742639201817}