{"uuid": "4744e2c5-51eb-4996-ad66-b67ccdc078bf", "children": ["9c1b0807-2e8b-47cc-9e75-e6dd0778fc7a"], "befores": [{"name": "driver", "status": "broken", "statusDetails": {"message": "selenium.common.exceptions.SessionNotCreatedException: Message: session not created: probably user data directory is already in use, please specify a unique value for --user-data-dir argument, or don't use --user-data-dir\nStacktrace:\n#0 0x55b211173ffa <unknown>\n#1 0x55b210c32970 <unknown>\n#2 0x55b210c6c42a <unknown>\n#3 0x55b210c6818f <unknown>\n#4 0x55b210cb8bd9 <unknown>\n#5 0x55b210cb8106 <unknown>\n#6 0x55b210caa063 <unknown>\n#7 0x55b210c76328 <unknown>\n#8 0x55b210c77491 <unknown>\n#9 0x55b21113b42b <unknown>\n#10 0x55b21113f2ec <unknown>\n#11 0x55b211122a22 <unknown>\n#12 0x55b21113fe64 <unknown>\n#13 0x55b211106bef <unknown>\n#14 0x55b211162558 <unknown>\n#15 0x55b211162736 <unknown>\n#16 0x55b211172e76 <unknown>\n#17 0x7fa92b3461f5 <unknown>\n\n", "trace": "  File \"/usr/local/lib/python3.9/site-packages/pluggy/_callers.py\", line 103, in _multicall\n    res = hook_impl.function(*args)\n  File \"/usr/local/lib/python3.9/site-packages/_pytest/fixtures.py\", line 1130, in pytest_fixture_setup\n    result = call_fixture_func(fixturefunc, request, kwargs)\n  File \"/usr/local/lib/python3.9/site-packages/_pytest/fixtures.py\", line 902, in call_fixture_func\n    fixture_result = next(generator)\n  File \"/app/tests/ui/ui_tests/conftest.py\", line 15, in driver\n    config_driver = webdriver.Chrome(service=service, options=options)\n  File \"/usr/local/lib/python3.9/site-packages/selenium/webdriver/chrome/webdriver.py\", line 49, in __init__\n    super().__init__(\n  File \"/usr/local/lib/python3.9/site-packages/selenium/webdriver/chromium/webdriver.py\", line 54, in __init__\n    super().__init__(\n  File \"/usr/local/lib/python3.9/site-packages/selenium/webdriver/remote/webdriver.py\", line 206, in __init__\n    self.start_session(capabilities)\n  File \"/usr/local/lib/python3.9/site-packages/selenium/webdriver/remote/webdriver.py\", line 291, in start_session\n    response = self.execute(Command.NEW_SESSION, caps)[\"value\"]\n  File \"/usr/local/lib/python3.9/site-packages/selenium/webdriver/remote/webdriver.py\", line 346, in execute\n    self.error_handler.check_response(response)\n  File \"/usr/local/lib/python3.9/site-packages/selenium/webdriver/remote/errorhandler.py\", line 245, in check_response\n    raise exception_class(message, screen, stacktrace)\n"}, "start": 1742639197019, "stop": 1742639199650}], "start": 1742639197019, "stop": 1742639199774}