{"uuid": "6cb8d997-68b6-4595-a091-e87a81111825", "children": ["5beaeaa8-7210-45c2-b0e6-5f6645c53a79"], "befores": [{"name": "driver", "status": "broken", "statusDetails": {"message": "selenium.common.exceptions.SessionNotCreatedException: Message: session not created: probably user data directory is already in use, please specify a unique value for --user-data-dir argument, or don't use --user-data-dir\nStacktrace:\n#0 0x55f3c3302ffa <unknown>\n#1 0x55f3c2dc1970 <unknown>\n#2 0x55f3c2dfb42a <unknown>\n#3 0x55f3c2df718f <unknown>\n#4 0x55f3c2e47bd9 <unknown>\n#5 0x55f3c2e47106 <unknown>\n#6 0x55f3c2e39063 <unknown>\n#7 0x55f3c2e05328 <unknown>\n#8 0x55f3c2e06491 <unknown>\n#9 0x55f3c32ca42b <unknown>\n#10 0x55f3c32ce2ec <unknown>\n#11 0x55f3c32b1a22 <unknown>\n#12 0x55f3c32cee64 <unknown>\n#13 0x55f3c3295bef <unknown>\n#14 0x55f3c32f1558 <unknown>\n#15 0x55f3c32f1736 <unknown>\n#16 0x55f3c3301e76 <unknown>\n#17 0x7f432c65f1f5 <unknown>\n\n", "trace": "  File \"/usr/local/lib/python3.9/site-packages/pluggy/_callers.py\", line 103, in _multicall\n    res = hook_impl.function(*args)\n  File \"/usr/local/lib/python3.9/site-packages/_pytest/fixtures.py\", line 1130, in pytest_fixture_setup\n    result = call_fixture_func(fixturefunc, request, kwargs)\n  File \"/usr/local/lib/python3.9/site-packages/_pytest/fixtures.py\", line 902, in call_fixture_func\n    fixture_result = next(generator)\n  File \"/app/tests/ui/ui_tests/conftest.py\", line 15, in driver\n    config_driver = webdriver.Chrome(service=service, options=options)\n  File \"/usr/local/lib/python3.9/site-packages/selenium/webdriver/chrome/webdriver.py\", line 49, in __init__\n    super().__init__(\n  File \"/usr/local/lib/python3.9/site-packages/selenium/webdriver/chromium/webdriver.py\", line 54, in __init__\n    super().__init__(\n  File \"/usr/local/lib/python3.9/site-packages/selenium/webdriver/remote/webdriver.py\", line 206, in __init__\n    self.start_session(capabilities)\n  File \"/usr/local/lib/python3.9/site-packages/selenium/webdriver/remote/webdriver.py\", line 291, in start_session\n    response = self.execute(Command.NEW_SESSION, caps)[\"value\"]\n  File \"/usr/local/lib/python3.9/site-packages/selenium/webdriver/remote/webdriver.py\", line 346, in execute\n    self.error_handler.check_response(response)\n  File \"/usr/local/lib/python3.9/site-packages/selenium/webdriver/remote/errorhandler.py\", line 245, in check_response\n    raise exception_class(message, screen, stacktrace)\n"}, "start": 1742639207602, "stop": 1742639208555}], "start": 1742639207602, "stop": 1742639208630}