{"uuid": "5cea0c8b-8fc5-4828-92b5-db6edd36a56e", "children": ["870066c8-6eeb-417f-a041-75df643042d3"], "befores": [{"name": "driver", "status": "broken", "statusDetails": {"message": "selenium.common.exceptions.SessionNotCreatedException: Message: session not created: probably user data directory is already in use, please specify a unique value for --user-data-dir argument, or don't use --user-data-dir\nStacktrace:\n#0 0x555bd811effa <unknown>\n#1 0x555bd7bdd970 <unknown>\n#2 0x555bd7c1742a <unknown>\n#3 0x555bd7c1318f <unknown>\n#4 0x555bd7c63bd9 <unknown>\n#5 0x555bd7c63106 <unknown>\n#6 0x555bd7c55063 <unknown>\n#7 0x555bd7c21328 <unknown>\n#8 0x555bd7c22491 <unknown>\n#9 0x555bd80e642b <unknown>\n#10 0x555bd80ea2ec <unknown>\n#11 0x555bd80cda22 <unknown>\n#12 0x555bd80eae64 <unknown>\n#13 0x555bd80b1bef <unknown>\n#14 0x555bd810d558 <unknown>\n#15 0x555bd810d736 <unknown>\n#16 0x555bd811de76 <unknown>\n#17 0x7f8ec94bd1f5 <unknown>\n\n", "trace": "  File \"/usr/local/lib/python3.9/site-packages/pluggy/_callers.py\", line 103, in _multicall\n    res = hook_impl.function(*args)\n  File \"/usr/local/lib/python3.9/site-packages/_pytest/fixtures.py\", line 1130, in pytest_fixture_setup\n    result = call_fixture_func(fixturefunc, request, kwargs)\n  File \"/usr/local/lib/python3.9/site-packages/_pytest/fixtures.py\", line 902, in call_fixture_func\n    fixture_result = next(generator)\n  File \"/app/tests/ui/ui_tests/conftest.py\", line 15, in driver\n    config_driver = webdriver.Chrome(service=service, options=options)\n  File \"/usr/local/lib/python3.9/site-packages/selenium/webdriver/chrome/webdriver.py\", line 49, in __init__\n    super().__init__(\n  File \"/usr/local/lib/python3.9/site-packages/selenium/webdriver/chromium/webdriver.py\", line 54, in __init__\n    super().__init__(\n  File \"/usr/local/lib/python3.9/site-packages/selenium/webdriver/remote/webdriver.py\", line 206, in __init__\n    self.start_session(capabilities)\n  File \"/usr/local/lib/python3.9/site-packages/selenium/webdriver/remote/webdriver.py\", line 291, in start_session\n    response = self.execute(Command.NEW_SESSION, caps)[\"value\"]\n  File \"/usr/local/lib/python3.9/site-packages/selenium/webdriver/remote/webdriver.py\", line 346, in execute\n    self.error_handler.check_response(response)\n  File \"/usr/local/lib/python3.9/site-packages/selenium/webdriver/remote/errorhandler.py\", line 245, in check_response\n    raise exception_class(message, screen, stacktrace)\n"}, "start": 1742639210642, "stop": 1742639211575}], "start": 1742639210642, "stop": 1742639211656}