{"uuid": "60a5fe01-e76b-4b4c-aedd-2c14021f0f2a", "children": ["bcd6a236-2939-496f-bfcb-83a84cf82bc9"], "befores": [{"name": "driver", "status": "broken", "statusDetails": {"message": "selenium.common.exceptions.SessionNotCreatedException: Message: session not created: probably user data directory is already in use, please specify a unique value for --user-data-dir argument, or don't use --user-data-dir\nStacktrace:\n#0 0x558286171ffa <unknown>\n#1 0x558285c30970 <unknown>\n#2 0x558285c6a42a <unknown>\n#3 0x558285c6618f <unknown>\n#4 0x558285cb6bd9 <unknown>\n#5 0x558285cb6106 <unknown>\n#6 0x558285ca8063 <unknown>\n#7 0x558285c74328 <unknown>\n#8 0x558285c75491 <unknown>\n#9 0x55828613942b <unknown>\n#10 0x55828613d2ec <unknown>\n#11 0x558286120a22 <unknown>\n#12 0x55828613de64 <unknown>\n#13 0x558286104bef <unknown>\n#14 0x558286160558 <unknown>\n#15 0x558286160736 <unknown>\n#16 0x558286170e76 <unknown>\n#17 0x7f7bbd9261f5 <unknown>\n\n", "trace": "  File \"/usr/local/lib/python3.9/site-packages/pluggy/_callers.py\", line 103, in _multicall\n    res = hook_impl.function(*args)\n  File \"/usr/local/lib/python3.9/site-packages/_pytest/fixtures.py\", line 1130, in pytest_fixture_setup\n    result = call_fixture_func(fixturefunc, request, kwargs)\n  File \"/usr/local/lib/python3.9/site-packages/_pytest/fixtures.py\", line 902, in call_fixture_func\n    fixture_result = next(generator)\n  File \"/app/tests/ui/ui_tests/conftest.py\", line 15, in driver\n    config_driver = webdriver.Chrome(service=service, options=options)\n  File \"/usr/local/lib/python3.9/site-packages/selenium/webdriver/chrome/webdriver.py\", line 49, in __init__\n    super().__init__(\n  File \"/usr/local/lib/python3.9/site-packages/selenium/webdriver/chromium/webdriver.py\", line 54, in __init__\n    super().__init__(\n  File \"/usr/local/lib/python3.9/site-packages/selenium/webdriver/remote/webdriver.py\", line 206, in __init__\n    self.start_session(capabilities)\n  File \"/usr/local/lib/python3.9/site-packages/selenium/webdriver/remote/webdriver.py\", line 291, in start_session\n    response = self.execute(Command.NEW_SESSION, caps)[\"value\"]\n  File \"/usr/local/lib/python3.9/site-packages/selenium/webdriver/remote/webdriver.py\", line 346, in execute\n    self.error_handler.check_response(response)\n  File \"/usr/local/lib/python3.9/site-packages/selenium/webdriver/remote/errorhandler.py\", line 245, in check_response\n    raise exception_class(message, screen, stacktrace)\n"}, "start": 1742639211684, "stop": 1742639212588}], "start": 1742639211684, "stop": 1742639212634}