{"name": "test_create_invalid_task_by_auth_user", "status": "failed", "statusDetails": {"message": "AssertionError: Expected 400, got 201", "trace": "@allure.feature(\"Tasks\")\n    @allure.story(\"Create an invalid task by authenticated user\")\n    @allure.severity(allure.severity_level.MINOR)\n    \n    def test_create_invalid_task_by_auth_user():\n        session = requests.Session()\n        with allure.step(\"Authenticating user\"):\n            auth = AuthenticateUser()\n            auth.login_user(valid_user, session)\n            assert auth.response.status_code == 200, f\"Login failed: {auth.response_json}\"\n        with allure.step(\"Creating task with invalid data\"):\n            new_invalid_task_by_auth_user = Task()\n            new_invalid_task_by_auth_user.new_task(invalid_new_task, session)\n        with allure.step(\"Checking response status is 400\"):\n>           new_invalid_task_by_auth_user.check_response_is_400(), \"Task is successfully created with empty values\"\n\ntests/api/tests/test_full_cycle.py:73: \n_ _ _ _ _ _ _ _ _ _ _ _ _ _ _ _ _ _ _ _ _ _ _ _ _ _ _ _ _ _ _ _ _ _ _ _ _ _ _ _ _ _ _ _ _ _ _ _ _ _ _ _ _ _ _ _ _ _ _ _ _ _ _ _ _ _ _ _ _ _ _ _ _ _ _ _ _ _ _ _ _ _ _ _ _ _ _ _ _ _ \n\nself = <tests.api.endpoints.operations_with_task.Task object at 0x7ffaf464fac0>\n\n    def check_response_is_400(self):\n>       assert self.response.status_code == 400,\\\n            f'Expected 400, got {self.response.status_code}'\nE       AssertionError: Expected 400, got 201\n\ntests/api/endpoints/base_endpoint.py:27: AssertionError"}, "steps": [{"name": "Authenticating user", "status": "passed", "start": 1742314623231, "stop": 1742314623484}, {"name": "Creating task with invalid data", "status": "passed", "start": 1742314623484, "stop": 1742314623510}, {"name": "Checking response status is 400", "status": "failed", "statusDetails": {"message": "AssertionError: Expected 400, got 201\n", "trace": "  File \"/app/tests/api/tests/test_full_cycle.py\", line 73, in test_create_invalid_task_by_auth_user\n    new_invalid_task_by_auth_user.check_response_is_400(), \"Task is successfully created with empty values\"\n  File \"/app/tests/api/endpoints/base_endpoint.py\", line 27, in check_response_is_400\n    assert self.response.status_code == 400,\\\n"}, "start": 1742314623510, "stop": 1742314623510}], "start": 1742314623230, "stop": 1742314623523, "uuid": "070227df-27da-4f11-bb7f-252c003b9996", "historyId": "fe00128b11a958af629ed9a4610e1079", "testCaseId": "fe00128b11a958af629ed9a4610e1079", "fullName": "tests.api.tests.test_full_cycle#test_create_invalid_task_by_auth_user", "labels": [{"name": "severity", "value": "minor"}, {"name": "story", "value": "Create an invalid task by authenticated user"}, {"name": "feature", "value": "Tasks"}, {"name": "parentSuite", "value": "tests.api.tests"}, {"name": "suite", "value": "test_full_cycle"}, {"name": "host", "value": "01f4c774ef79"}, {"name": "thread", "value": "7-MainThread"}, {"name": "framework", "value": "pytest"}, {"name": "language", "value": "cpython3"}, {"name": "package", "value": "tests.api.tests.test_full_cycle"}]}