{"uuid": "c287bfdf-aae8-4b29-b9ac-54d9965951c0", "children": ["1bbd29da-a305-4489-bcc8-b5fd33f8071b"], "befores": [{"name": "driver", "status": "broken", "statusDetails": {"message": "selenium.common.exceptions.SessionNotCreatedException: Message: session not created: probably user data directory is already in use, please specify a unique value for --user-data-dir argument, or don't use --user-data-dir\nStacktrace:\n#0 0x558a304d6ffa <unknown>\n#1 0x558a2ff95970 <unknown>\n#2 0x558a2ffcf42a <unknown>\n#3 0x558a2ffcb18f <unknown>\n#4 0x558a3001bbd9 <unknown>\n#5 0x558a3001b106 <unknown>\n#6 0x558a3000d063 <unknown>\n#7 0x558a2ffd9328 <unknown>\n#8 0x558a2ffda491 <unknown>\n#9 0x558a3049e42b <unknown>\n#10 0x558a304a22ec <unknown>\n#11 0x558a30485a22 <unknown>\n#12 0x558a304a2e64 <unknown>\n#13 0x558a30469bef <unknown>\n#14 0x558a304c5558 <unknown>\n#15 0x558a304c5736 <unknown>\n#16 0x558a304d5e76 <unknown>\n#17 0x7fa00b7b21f5 <unknown>\n\n", "trace": "  File \"/usr/local/lib/python3.9/site-packages/pluggy/_callers.py\", line 103, in _multicall\n    res = hook_impl.function(*args)\n  File \"/usr/local/lib/python3.9/site-packages/_pytest/fixtures.py\", line 1130, in pytest_fixture_setup\n    result = call_fixture_func(fixturefunc, request, kwargs)\n  File \"/usr/local/lib/python3.9/site-packages/_pytest/fixtures.py\", line 902, in call_fixture_func\n    fixture_result = next(generator)\n  File \"/app/tests/ui/ui_tests/conftest.py\", line 15, in driver\n    config_driver = webdriver.Chrome(service=service, options=options)\n  File \"/usr/local/lib/python3.9/site-packages/selenium/webdriver/chrome/webdriver.py\", line 49, in __init__\n    super().__init__(\n  File \"/usr/local/lib/python3.9/site-packages/selenium/webdriver/chromium/webdriver.py\", line 54, in __init__\n    super().__init__(\n  File \"/usr/local/lib/python3.9/site-packages/selenium/webdriver/remote/webdriver.py\", line 206, in __init__\n    self.start_session(capabilities)\n  File \"/usr/local/lib/python3.9/site-packages/selenium/webdriver/remote/webdriver.py\", line 291, in start_session\n    response = self.execute(Command.NEW_SESSION, caps)[\"value\"]\n  File \"/usr/local/lib/python3.9/site-packages/selenium/webdriver/remote/webdriver.py\", line 346, in execute\n    self.error_handler.check_response(response)\n  File \"/usr/local/lib/python3.9/site-packages/selenium/webdriver/remote/errorhandler.py\", line 245, in check_response\n    raise exception_class(message, screen, stacktrace)\n"}, "start": 1742639203987, "stop": 1742639205188}], "start": 1742639203987, "stop": 1742639205233}