{"uuid": "4653481c-94a1-4699-be8c-d68b43678eb5", "children": ["956d52bb-8899-4a9d-adc2-8cc9d6e015b9"], "befores": [{"name": "driver", "status": "broken", "statusDetails": {"message": "selenium.common.exceptions.SessionNotCreatedException: Message: session not created: probably user data directory is already in use, please specify a unique value for --user-data-dir argument, or don't use --user-data-dir\nStacktrace:\n#0 0x555cbb14bffa <unknown>\n#1 0x555cbac0a970 <unknown>\n#2 0x555cbac4442a <unknown>\n#3 0x555cbac4018f <unknown>\n#4 0x555cbac90bd9 <unknown>\n#5 0x555cbac90106 <unknown>\n#6 0x555cbac82063 <unknown>\n#7 0x555cbac4e328 <unknown>\n#8 0x555cbac4f491 <unknown>\n#9 0x555cbb11342b <unknown>\n#10 0x555cbb1172ec <unknown>\n#11 0x555cbb0faa22 <unknown>\n#12 0x555cbb117e64 <unknown>\n#13 0x555cbb0debef <unknown>\n#14 0x555cbb13a558 <unknown>\n#15 0x555cbb13a736 <unknown>\n#16 0x555cbb14ae76 <unknown>\n#17 0x7efe3b45a1f5 <unknown>\n\n", "trace": "  File \"/usr/local/lib/python3.9/site-packages/pluggy/_callers.py\", line 103, in _multicall\n    res = hook_impl.function(*args)\n  File \"/usr/local/lib/python3.9/site-packages/_pytest/fixtures.py\", line 1130, in pytest_fixture_setup\n    result = call_fixture_func(fixturefunc, request, kwargs)\n  File \"/usr/local/lib/python3.9/site-packages/_pytest/fixtures.py\", line 902, in call_fixture_func\n    fixture_result = next(generator)\n  File \"/app/tests/ui/ui_tests/conftest.py\", line 15, in driver\n    config_driver = webdriver.Chrome(service=service, options=options)\n  File \"/usr/local/lib/python3.9/site-packages/selenium/webdriver/chrome/webdriver.py\", line 49, in __init__\n    super().__init__(\n  File \"/usr/local/lib/python3.9/site-packages/selenium/webdriver/chromium/webdriver.py\", line 54, in __init__\n    super().__init__(\n  File \"/usr/local/lib/python3.9/site-packages/selenium/webdriver/remote/webdriver.py\", line 206, in __init__\n    self.start_session(capabilities)\n  File \"/usr/local/lib/python3.9/site-packages/selenium/webdriver/remote/webdriver.py\", line 291, in start_session\n    response = self.execute(Command.NEW_SESSION, caps)[\"value\"]\n  File \"/usr/local/lib/python3.9/site-packages/selenium/webdriver/remote/webdriver.py\", line 346, in execute\n    self.error_handler.check_response(response)\n  File \"/usr/local/lib/python3.9/site-packages/selenium/webdriver/remote/errorhandler.py\", line 245, in check_response\n    raise exception_class(message, screen, stacktrace)\n"}, "start": 1742639201844, "stop": 1742639202771}], "start": 1742639201844, "stop": 1742639202853}